<?xml version="1.0" ?>
<!-- =================================================================================== -->
<!-- |    This document was autogenerated by xacro from /home/robot/catkin_ws/src/yonsoku_robot_description/urdf/yonsoku_robot.urdf.xacro | -->
<!-- |    EDITING THIS FILE BY HAND IS NOT RECOMMENDED                                 | -->
<!-- =================================================================================== -->
<robot name="yonsoku_robot">
  <!-- link rviz colors -->
  <material name="White">
    <color rgba="1 1 1 1"/>
  </material>
  <material name="Black">
    <color rgba="0 0 0 1"/>
  </material>
  <!-- new base link -->
  <link name="base_link">
    </link>
  <!-- joint between base_link and body_link -->
  <joint name="base_to_body" type="fixed">
    <origin rpy="0 0 0" xyz="0 0 0"/>
    <parent link="base_link"/>
    <child link="body_link"/>
  </joint>
  <!-- body link -->
  <link name="body_link">
    <visual>
      <origin rpy="0 0 0" xyz="0 0 0"/>
      <geometry>
        <mesh filename="package://yonsoku_robot_description/meshes/base.stl" scale="0.001 0.001 0.001"/>
      </geometry>
      <material name="White"/>
    </visual>
    <collision>
      <origin rpy="0 0 0" xyz="0 0 0"/>
      <geometry>
        <mesh filename="package://yonsoku_robot_description/meshes/base.stl" scale="0.001 0.001 0.001"/>
      </geometry>
    </collision>
    <inertial>
      <mass value="12.72349"/>
      <origin rpy="0 0 0" xyz="-0.00 0.00 -0.00474"/>
      <inertia ixx="0.1" ixy="0.0000" ixz="0.000000" iyy="0.1" iyz="0.0" izz="0.1"/>
    </inertial>
  </link>
  <!-- IMU sensor -->
  <link name="imu_link">
    <inertial>
      <mass value="0.001"/>
      <origin rpy="0 0 0" xyz="0 0 0"/>
      <inertia ixx="0.000001" ixy="0.0" ixz="0.0" iyy="0.000001" iyz="0.0" izz="0.000001"/>
    </inertial>
    <visual>
      <geometry>
        <box size="0.05 0.05 0.05"/>
      </geometry>
      <origin rpy="0 0 0" xyz="0 0 0"/>
    </visual>
  </link>
  <joint name="base_to_imu" type="fixed">
    <parent link="base_link"/>
    <child link="imu_link"/>
    <origin rpy="0 0 0" xyz="0 0 0"/>
  </joint>
  <gazebo>
    <plugin filename="libgazebo_ros_imu.so" name="imu_plugin">
      <ros>
        <remapping>my_imu:=/imu/data</remapping>
      </ros>
      <alwaysOn>true</alwaysOn>
      <updateRate>50.0</updateRate>
      <bodyName>imu_link</bodyName>
      <gaussianNoise>0.0</gaussianNoise>
    </plugin>
  </gazebo>
  <!-- left forward joint -->
  <joint name="base_to_left_forward_base" type="fixed">
    <origin rpy="0 0 0" xyz="0.3000 0.0800 0"/>
    <parent link="body_link"/>
    <child link="LF_FOOT"/>
  </joint>
  <!-- base link -->
  <link name="LF_FOOT">
    <inertial>
      <mass value="0.001"/>
      <inertia ixx="0.000000" ixy="0.000000" ixz="0.000000" iyy="0.000000" iyz="0.000000" izz="0.000000"/>
    </inertial>
  </link>
  <!-- joint 1 -->
  <joint name="LF_JOINT1" type="revolute">
    <origin rpy="0 0 0" xyz="0 0 0.0"/>
    <axis rpy="0 0 0" xyz="1 0 0"/>
    <limit effort="1000.0" lower="-6.283185307179586" upper="6.283185307179586" velocity="6.283185307179586"/>
    <parent link="LF_FOOT"/>
    <child link="LF1"/>
  </joint>
  <!-- link 1 -->
  <link name="LF1">
    <visual>
      <origin rpy="0 0 0" xyz="0 0 0"/>
      <geometry>
        <mesh filename="package://yonsoku_robot_description/meshes/lf_hip.stl"/>
      </geometry>
      <material name="White"/>
    </visual>
    <collision>
      <origin rpy="0 0 0" xyz="0 0 0"/>
      <geometry>
        <mesh filename="package://yonsoku_robot_description/meshes/lf_hip.stl" scale="0.002 0.002 0.002"/>
      </geometry>
      <surface>
        <friction>
          <ode>
            <mu>1.0</mu>
            <mu2>1.0</mu2>
          </ode>
        </friction>
      </surface>
    </collision>
    <inertial>
      <origin xyz="-0.00 -0.0 0.00000"/>
      <mass value="1.23047"/>
      <inertia ixx="0.1" ixy="0.0000" ixz="0.000000" iyy="0.1" iyz="0.0" izz="0.1"/>
    </inertial>
  </link>
  <!-- joint 2 -->
  <joint name="LF_JOINT2" type="continuous">
    <origin rpy="0 0 0" xyz="0 0.1000 0"/>
    <axis rpy="0 0 0" xyz="0 1 0"/>
    <limit effort="1000.0" lower="-6.283185307179586" upper="6.283185307179586" velocity="6.283185307179586"/>
    <parent link="LF1"/>
    <child link="LF2"/>
  </joint>
  <!-- link 2 -->
  <link name="LF2">
    <visual>
      <origin rpy="0 0 0" xyz="0 0 0"/>
      <geometry>
        <mesh filename="package://yonsoku_robot_description/meshes/l_upper_leg.stl"/>
      </geometry>
      <material name="White"/>
    </visual>
    <collision>
      <origin rpy="0 0 0" xyz="0 0 0"/>
      <geometry>
        <mesh filename="package://yonsoku_robot_description/meshes/l_upper_leg.stl"/>
      </geometry>
      <surface>
        <friction>
          <ode>
            <mu>1.0</mu>
            <mu2>1.0</mu2>
          </ode>
        </friction>
      </surface>
    </collision>
    <inertial>
      <origin xyz="0.00006 -0.0 -0.05962"/>
      <mass value="2.06632"/>
      <inertia ixx="0.1" ixy="0.0000" ixz="0.000000" iyy="0.1" iyz="0.0" izz="0.1"/>
    </inertial>
  </link>
  <!-- joint 3 -->
  <joint name="LF_JOINT3" type="revolute">
    <axis rpy="0 0 0" xyz="0 1 0"/>
    <limit effort="1000.0" lower="-6.283185307179586" upper="6.283185307179586" velocity="6.283185307179586"/>
    <origin rpy="0 0 0" xyz="0 0 -0.2800"/>
    <parent link="LF2"/>
    <child link="LF3"/>
  </joint>
  <!-- link 3 -->
  <link name="LF3">
    <visual>
      <origin rpy="0 0 0" xyz="0 0 0"/>
      <geometry>
        <mesh filename="package://yonsoku_robot_description/meshes/lower_leg.stl"/>
      </geometry>
      <material name="White"/>
    </visual>
    <collision>
      <origin rpy="0 0 0" xyz="0 0 0"/>
      <geometry>
        <mesh filename="package://yonsoku_robot_description/meshes/lower_leg.stl"/>
      </geometry>
      <surface>
        <friction>
          <ode>
            <mu>1.0</mu>
            <mu2>1.0</mu2>
          </ode>
        </friction>
      </surface>
    </collision>
    <inertial>
      <origin xyz="0.00000 -0.00 -0.19822"/>
      <mass value="0.41492"/>
      <inertia ixx="0.1" ixy="0.0000" ixz="0.000000" iyy="0.1" iyz="0.0" izz="0.1"/>
    </inertial>
  </link>
  <!-- transmissions -->
  <transmission name="LF_transmission1">
    <type>transmission_interface/SimpleTransmission</type>
    <joint name="LF_JOINT1">
      <!-- <hardwareInterface>hardware_interface/PositionJointInterface</hardwareInterface> -->
      <hardwareInterface>hardware_interface/EffortJointInterface</hardwareInterface>
    </joint>
    <actuator name="LF_actuator1">
      <mechanicalReduction>1</mechanicalReduction>
    </actuator>
  </transmission>
  <transmission name="LF_transmission2">
    <type>transmission_interface/SimpleTransmission</type>
    <joint name="LF_JOINT2">
      <!-- <hardwareInterface>hardware_interface/PositionJointInterface</hardwareInterface> -->
      <hardwareInterface>hardware_interface/EffortJointInterface</hardwareInterface>
    </joint>
    <actuator name="LF_actuator2">
      <mechanicalReduction>1</mechanicalReduction>
    </actuator>
  </transmission>
  <transmission name="LF_transmission3">
    <type>transmission_interface/SimpleTransmission</type>
    <joint name="LF_JOINT3">
      <!-- <hardwareInterface>hardware_interface/PositonJointInterface</hardwareInterface> -->
      <hardwareInterface>hardware_interface/EffortJointInterface</hardwareInterface>
    </joint>
    <actuator name="LF_actuator3">
      <mechanicalReduction>1</mechanicalReduction>
    </actuator>
  </transmission>
  <!-- right forward joint -->
  <joint name="base_to_right_forward_base" type="fixed">
    <origin rpy="0 0 0" xyz="0.3000 -0.0800 0"/>
    <parent link="body_link"/>
    <child link="RF_FOOT"/>
  </joint>
  <!-- base link -->
  <link name="RF_FOOT">
    <inertial>
      <mass value="0.001"/>
      <inertia ixx="0.000000" ixy="0.000000" ixz="0.000000" iyy="0.000000" iyz="0.000000" izz="0.000000"/>
    </inertial>
  </link>
  <!-- joint 1 -->
  <joint name="RF_JOINT1" type="revolute">
    <origin rpy="0 0 0" xyz="0 0 0.0"/>
    <axis rpy="0 0 0" xyz="1 0 0"/>
    <limit effort="1000.0" lower="-6.283185307179586" upper="6.283185307179586" velocity="6.283185307179586"/>
    <parent link="RF_FOOT"/>
    <child link="RF1"/>
  </joint>
  <!-- link 1 -->
  <link name="RF1">
    <visual>
      <origin rpy="0 0 0" xyz="0 0 0"/>
      <geometry>
        <mesh filename="package://yonsoku_robot_description/meshes/rf_hip.stl"/>
      </geometry>
      <material name="White"/>
    </visual>
    <collision>
      <origin rpy="0 0 0" xyz="0 0 0"/>
      <geometry>
        <mesh filename="package://yonsoku_robot_description/meshes/rf_hip.stl" scale="0.002 0.002 0.002"/>
      </geometry>
      <surface>
        <friction>
          <ode>
            <mu>1.0</mu>
            <mu2>1.0</mu2>
          </ode>
        </friction>
      </surface>
    </collision>
    <inertial>
      <origin xyz="-0.00 -0.0 0.00000"/>
      <mass value="1.23047"/>
      <inertia ixx="0.1" ixy="0.0000" ixz="0.000000" iyy="0.1" iyz="0.0" izz="0.1"/>
    </inertial>
  </link>
  <!-- joint 2 -->
  <joint name="RF_JOINT2" type="continuous">
    <origin rpy="0 0 0" xyz="0 -0.1000  0"/>
    <axis rpy="0 0 0" xyz="0 1 0"/>
    <limit effort="1000.0" lower="-6.283185307179586" upper="6.283185307179586" velocity="6.283185307179586"/>
    <parent link="RF1"/>
    <child link="RF2"/>
  </joint>
  <!-- link 2 -->
  <link name="RF2">
    <visual>
      <origin rpy="0 0 0" xyz="0 0 0"/>
      <geometry>
        <mesh filename="package://yonsoku_robot_description/meshes/r_upper_leg.stl"/>
      </geometry>
      <material name="White"/>
    </visual>
    <collision>
      <origin rpy="0 0 0" xyz="0 0 0"/>
      <geometry>
        <mesh filename="package://yonsoku_robot_description/meshes/r_upper_leg.stl"/>
      </geometry>
      <surface>
        <friction>
          <ode>
            <mu>1.0</mu>
            <mu2>1.0</mu2>
          </ode>
        </friction>
      </surface>
    </collision>
    <inertial>
      <origin xyz="0.00006 -0.0 -0.05962"/>
      <mass value="2.06632"/>
      <inertia ixx="0.1" ixy="0.0000" ixz="0.000000" iyy="0.1" iyz="0.0" izz="0.1"/>
    </inertial>
  </link>
  <!-- joint 3 -->
  <joint name="RF_JOINT3" type="revolute">
    <axis rpy="0 0 0" xyz="0 1 0"/>
    <limit effort="1000.0" lower="-6.283185307179586" upper="6.283185307179586" velocity="6.283185307179586"/>
    <origin rpy="0 0 0" xyz="0 0 -0.2800"/>
    <parent link="RF2"/>
    <child link="RF3"/>
  </joint>
  <!-- link 3 -->
  <link name="RF3">
    <visual>
      <origin rpy="0 0 0" xyz="0 0 0"/>
      <geometry>
        <mesh filename="package://yonsoku_robot_description/meshes/lower_leg.stl"/>
      </geometry>
      <material name="White"/>
    </visual>
    <collision>
      <origin rpy="0 0 0" xyz="0 0 0"/>
      <geometry>
        <mesh filename="package://yonsoku_robot_description/meshes/lower_leg.stl"/>
      </geometry>
      <surface>
        <friction>
          <ode>
            <mu>1.0</mu>
            <mu2>1.0</mu2>
          </ode>
        </friction>
      </surface>
    </collision>
    <inertial>
      <origin xyz="0.00000 -0.00 -0.19822"/>
      <mass value="0.41492"/>
      <inertia ixx="0.1" ixy="0.0000" ixz="0.000000" iyy="0.1" iyz="0.0" izz="0.1"/>
    </inertial>
  </link>
  <!-- transmissions -->
  <transmission name="RF_transmission1">
    <type>transmission_interface/SimpleTransmission</type>
    <joint name="RF_JOINT1">
      <!-- <hardwareInterface>hardware_interface/PositionJointInterface</hardwareInterface> -->
      <hardwareInterface>hardware_interface/EffortJointInterface</hardwareInterface>
    </joint>
    <actuator name="RF_actuator1">
      <mechanicalReduction>1</mechanicalReduction>
    </actuator>
  </transmission>
  <transmission name="RF_transmission2">
    <type>transmission_interface/SimpleTransmission</type>
    <joint name="RF_JOINT2">
      <!-- <hardwareInterface>hardware_interface/PositionJointInterface</hardwareInterface> -->
      <hardwareInterface>hardware_interface/EffortJointInterface</hardwareInterface>
    </joint>
    <actuator name="RF_actuator2">
      <mechanicalReduction>1</mechanicalReduction>
    </actuator>
  </transmission>
  <transmission name="RF_transmission3">
    <type>transmission_interface/SimpleTransmission</type>
    <joint name="RF_JOINT3">
      <!-- <hardwareInterface>hardware_interface/PositonJointInterface</hardwareInterface> -->
      <hardwareInterface>hardware_interface/EffortJointInterface</hardwareInterface>
    </joint>
    <actuator name="RF_actuator3">
      <mechanicalReduction>1</mechanicalReduction>
    </actuator>
  </transmission>
  <!-- left back joint -->
  <joint name="base_to_left_back_base" type="fixed">
    <origin rpy="0 0 0" xyz="-0.3000 0.0800 0"/>
    <parent link="body_link"/>
    <child link="LB_FOOT"/>
  </joint>
  <!-- base link -->
  <link name="LB_FOOT">
    <inertial>
      <mass value="0.001"/>
      <inertia ixx="0.000000" ixy="0.000000" ixz="0.000000" iyy="0.000000" iyz="0.000000" izz="0.000000"/>
    </inertial>
  </link>
  <!-- joint 1 -->
  <joint name="LB_JOINT1" type="revolute">
    <origin rpy="0 0 0" xyz="0 0 0.0"/>
    <axis rpy="0 0 0" xyz="1 0 0"/>
    <limit effort="1000.0" lower="-6.283185307179586" upper="6.283185307179586" velocity="6.283185307179586"/>
    <parent link="LB_FOOT"/>
    <child link="LB1"/>
  </joint>
  <!-- link 1 -->
  <link name="LB1">
    <visual>
      <origin rpy="0 0 0" xyz="0 0 0"/>
      <geometry>
        <mesh filename="package://yonsoku_robot_description/meshes/lb_hip.stl"/>
      </geometry>
      <material name="White"/>
    </visual>
    <collision>
      <origin rpy="0 0 0" xyz="0 0 0"/>
      <geometry>
        <mesh filename="package://yonsoku_robot_description/meshes/lb_hip.stl" scale="0.002 0.002 0.002"/>
      </geometry>
      <surface>
        <friction>
          <ode>
            <mu>1.0</mu>
            <mu2>1.0</mu2>
          </ode>
        </friction>
      </surface>
    </collision>
    <inertial>
      <origin xyz="-0.00 -0.0 0.00000"/>
      <mass value="1.23047"/>
      <inertia ixx="0.1" ixy="0.0000" ixz="0.000000" iyy="0.1" iyz="0.0" izz="0.1"/>
    </inertial>
  </link>
  <!-- joint 2 -->
  <joint name="LB_JOINT2" type="continuous">
    <origin rpy="0 0 0" xyz="0 0.1000 0"/>
    <axis rpy="0 0 0" xyz="0 1 0"/>
    <limit effort="1000.0" lower="-6.283185307179586" upper="6.283185307179586" velocity="6.283185307179586"/>
    <parent link="LB1"/>
    <child link="LB2"/>
  </joint>
  <!-- link 2 -->
  <link name="LB2">
    <visual>
      <origin rpy="0 0 0" xyz="0 0 0"/>
      <geometry>
        <mesh filename="package://yonsoku_robot_description/meshes/l_upper_leg.stl"/>
      </geometry>
      <material name="White"/>
    </visual>
    <collision>
      <origin rpy="0 0 0" xyz="0 0 0"/>
      <geometry>
        <mesh filename="package://yonsoku_robot_description/meshes/l_upper_leg.stl"/>
      </geometry>
      <surface>
        <friction>
          <ode>
            <mu>1.0</mu>
            <mu2>1.0</mu2>
          </ode>
        </friction>
      </surface>
    </collision>
    <inertial>
      <origin xyz="0.00006 -0.0 -0.05962"/>
      <mass value="2.06632"/>
      <inertia ixx="0.1" ixy="0.0000" ixz="0.000000" iyy="0.1" iyz="0.0" izz="0.1"/>
    </inertial>
  </link>
  <!-- joint 3 -->
  <joint name="LB_JOINT3" type="revolute">
    <axis rpy="0 0 0" xyz="0 1 0"/>
    <limit effort="1000.0" lower="-6.283185307179586" upper="6.283185307179586" velocity="6.283185307179586"/>
    <origin rpy="0 0 0" xyz="0 0 -0.2800"/>
    <parent link="LB2"/>
    <child link="LB3"/>
  </joint>
  <!-- link 3 -->
  <link name="LB3">
    <visual>
      <origin rpy="0 0 0" xyz="0 0 0"/>
      <geometry>
        <mesh filename="package://yonsoku_robot_description/meshes/lower_leg.stl"/>
      </geometry>
      <material name="White"/>
    </visual>
    <collision>
      <origin rpy="0 0 0" xyz="0 0 0"/>
      <geometry>
        <mesh filename="package://yonsoku_robot_description/meshes/lower_leg.stl"/>
      </geometry>
      <surface>
        <friction>
          <ode>
            <mu>1.0</mu>
            <mu2>1.0</mu2>
          </ode>
        </friction>
      </surface>
    </collision>
    <inertial>
      <origin xyz="0.00000 -0.00 -0.19822"/>
      <mass value="0.41492"/>
      <inertia ixx="0.1" ixy="0.0000" ixz="0.000000" iyy="0.1" iyz="0.0" izz="0.1"/>
    </inertial>
  </link>
  <!-- transmissions -->
  <transmission name="LB_transmission1">
    <type>transmission_interface/SimpleTransmission</type>
    <joint name="LB_JOINT1">
      <!-- <hardwareInterface>hardware_interface/PositionJointInterface</hardwareInterface> -->
      <hardwareInterface>hardware_interface/EffortJointInterface</hardwareInterface>
    </joint>
    <actuator name="LB_actuator1">
      <mechanicalReduction>1</mechanicalReduction>
    </actuator>
  </transmission>
  <transmission name="LB_transmission2">
    <type>transmission_interface/SimpleTransmission</type>
    <joint name="LB_JOINT2">
      <!-- <hardwareInterface>hardware_interface/PositionJointInterface</hardwareInterface> -->
      <hardwareInterface>hardware_interface/EffortJointInterface</hardwareInterface>
    </joint>
    <actuator name="LB_actuator2">
      <mechanicalReduction>1</mechanicalReduction>
    </actuator>
  </transmission>
  <transmission name="LB_transmission3">
    <type>transmission_interface/SimpleTransmission</type>
    <joint name="LB_JOINT3">
      <!-- <hardwareInterface>hardware_interface/PositonJointInterface</hardwareInterface> -->
      <hardwareInterface>hardware_interface/EffortJointInterface</hardwareInterface>
    </joint>
    <actuator name="LB_actuator3">
      <mechanicalReduction>1</mechanicalReduction>
    </actuator>
  </transmission>
  <!-- right back joint -->
  <joint name="base_to_right_back_base" type="fixed">
    <origin rpy="0 0 0" xyz="-0.3000 -0.0800 0"/>
    <parent link="body_link"/>
    <child link="RB_FOOT"/>
  </joint>
  <!-- base link -->
  <link name="RB_FOOT">
    <inertial>
      <mass value="0.001"/>
      <inertia ixx="0.000000" ixy="0.000000" ixz="0.000000" iyy="0.000000" iyz="0.000000" izz="0.000000"/>
    </inertial>
  </link>
  <!-- joint 1 -->
  <joint name="RB_JOINT1" type="revolute">
    <origin rpy="0 0 0" xyz="0 0 0.0"/>
    <axis rpy="0 0 0" xyz="1 0 0"/>
    <limit effort="1000.0" lower="-6.283185307179586" upper="6.283185307179586" velocity="6.283185307179586"/>
    <parent link="RB_FOOT"/>
    <child link="RB1"/>
  </joint>
  <!-- link 1 -->
  <link name="RB1">
    <visual>
      <origin rpy="0 0 0" xyz="0 0 0"/>
      <geometry>
        <mesh filename="package://yonsoku_robot_description/meshes/rb_hip.stl"/>
      </geometry>
      <material name="White"/>
    </visual>
    <collision>
      <origin rpy="0 0 0" xyz="0 0 0"/>
      <geometry>
        <mesh filename="package://yonsoku_robot_description/meshes/rb_hip.stl" scale="0.002 0.002 0.002"/>
      </geometry>
      <surface>
        <friction>
          <ode>
            <mu>1.0</mu>
            <mu2>1.0</mu2>
          </ode>
        </friction>
      </surface>
    </collision>
    <inertial>
      <origin xyz="-0.00 -0.0 0.00000"/>
      <mass value="1.23047"/>
      <inertia ixx="0.1" ixy="0.0000" ixz="0.000000" iyy="0.1" iyz="0.0" izz="0.1"/>
    </inertial>
  </link>
  <!-- joint 2 -->
  <joint name="RB_JOINT2" type="continuous">
    <origin rpy="0 0 0" xyz="0 -0.1000  0"/>
    <axis rpy="0 0 0" xyz="0 1 0"/>
    <limit effort="1000.0" lower="-6.283185307179586" upper="6.283185307179586" velocity="6.283185307179586"/>
    <parent link="RB1"/>
    <child link="RB2"/>
  </joint>
  <!-- link 2 -->
  <link name="RB2">
    <visual>
      <origin rpy="0 0 0" xyz="0 0 0"/>
      <geometry>
        <mesh filename="package://yonsoku_robot_description/meshes/r_upper_leg.stl"/>
      </geometry>
      <material name="White"/>
    </visual>
    <collision>
      <origin rpy="0 0 0" xyz="0 0 0"/>
      <geometry>
        <mesh filename="package://yonsoku_robot_description/meshes/r_upper_leg.stl"/>
      </geometry>
      <surface>
        <friction>
          <ode>
            <mu>1.0</mu>
            <mu2>1.0</mu2>
          </ode>
        </friction>
      </surface>
    </collision>
    <inertial>
      <origin xyz="0.00006 -0.0 -0.05962"/>
      <mass value="2.06632"/>
      <inertia ixx="0.1" ixy="0.0000" ixz="0.000000" iyy="0.1" iyz="0.0" izz="0.1"/>
    </inertial>
  </link>
  <!-- joint 3 -->
  <joint name="RB_JOINT3" type="revolute">
    <axis rpy="0 0 0" xyz="0 1 0"/>
    <limit effort="1000.0" lower="-6.283185307179586" upper="6.283185307179586" velocity="6.283185307179586"/>
    <origin rpy="0 0 0" xyz="0 0 -0.2800"/>
    <parent link="RB2"/>
    <child link="RB3"/>
  </joint>
  <!-- link 3 -->
  <link name="RB3">
    <visual>
      <origin rpy="0 0 0" xyz="0 0 0"/>
      <geometry>
        <mesh filename="package://yonsoku_robot_description/meshes/lower_leg.stl"/>
      </geometry>
      <material name="White"/>
    </visual>
    <collision>
      <origin rpy="0 0 0" xyz="0 0 0"/>
      <geometry>
        <mesh filename="package://yonsoku_robot_description/meshes/lower_leg.stl"/>
      </geometry>
      <surface>
        <friction>
          <ode>
            <mu>1.0</mu>
            <mu2>1.0</mu2>
          </ode>
        </friction>
      </surface>
    </collision>
    <inertial>
      <origin xyz="0.00000 -0.00 -0.19822"/>
      <mass value="0.41492"/>
      <inertia ixx="0.1" ixy="0.0000" ixz="0.000000" iyy="0.1" iyz="0.0" izz="0.1"/>
    </inertial>
  </link>
  <!-- transmissions -->
  <transmission name="RB_transmission1">
    <type>transmission_interface/SimpleTransmission</type>
    <joint name="RB_JOINT1">
      <!-- <hardwareInterface>hardware_interface/PositionJointInterface</hardwareInterface> -->
      <hardwareInterface>hardware_interface/EffortJointInterface</hardwareInterface>
    </joint>
    <actuator name="RB_actuator1">
      <mechanicalReduction>1</mechanicalReduction>
    </actuator>
  </transmission>
  <transmission name="RB_transmission2">
    <type>transmission_interface/SimpleTransmission</type>
    <joint name="RB_JOINT2">
      <!-- <hardwareInterface>hardware_interface/PositionJointInterface</hardwareInterface> -->
      <hardwareInterface>hardware_interface/EffortJointInterface</hardwareInterface>
    </joint>
    <actuator name="RB_actuator2">
      <mechanicalReduction>1</mechanicalReduction>
    </actuator>
  </transmission>
  <transmission name="RB_transmission3">
    <type>transmission_interface/SimpleTransmission</type>
    <joint name="RB_JOINT3">
      <!-- <hardwareInterface>hardware_interface/PositonJointInterface</hardwareInterface> -->
      <hardwareInterface>hardware_interface/EffortJointInterface</hardwareInterface>
    </joint>
    <actuator name="RB_actuator3">
      <mechanicalReduction>1</mechanicalReduction>
    </actuator>
  </transmission>
  <gazebo>
    <plugin filename="libgazebo_ros_control.so" name="gazebo_ros_control"/>
  </gazebo>
</robot>
